Workbook

Sheet 사용법
A1: 기본 사용법
B2: 1. 반드시 인터넷 익스플로러(크롬 안됨)를 이용해서, comp.fnguide.com(www.fnguide.com 아님)에 접속합니다.
B3: 2. 우상단 창에 원하는 종목을 입력하여 검색하신 후, snapshot 화면을 전체선택(ctrl + a)하고 복사하여(ctrl + c) "FN_Snapshot" 시트의 A1셀을 선택한 다음 '주변서식에 맞추기'로 붙여 넣습니다.
B4: 3. 결과 시트를 확인합니다.
A6: 크롬(Chrome) 사용법
B7: 1. 인터넷 익스플로러 서비스가 중단됨에 따라, 구글 크롬(Chrome)에서도 본 마법사를 활용하는 방법을 안내드립니다.
B8: 2. 크롬에서 chrome 웹 스토어(https://chrome.google.com/webstore/category/extensions?hl=ko)로 접속합니다.
B9: 3. 좌측 상단 '스토어 검색'에서 'IE Tab' (대소문자 관계 없음)을 검색합니다.
B25: 4. 첫번째로 나오는 IE Tab을 클릭하고, 우측에 있는 'Chrome에 추가' 버튼을 클릭하고, '확장 프로그램 추가'를 클릭합니다.
B39: 5. 즉시 추가가 되고, 우측 상단에 퍼즐모양 아이콘을 클릭하고 IE Tab을 클릭합니다.
B52: 6. 이제 IE Tab을 통해서 comp.fnguide.com으로 접속하고, 위의 '기본 사용법'을 따라 동일하게 진행합니다.
A56: RIM 수기계산 사용
B57: 여러 가지 에러 상황(정확한 원인은 알 수 없으나, 붙여넣기만 하면 엑셀이 그냥 다운되버린다는 경우 등이 간혹 있음)에 대비하여, 수기계산 시트 추가
B58: "[Type 1] 단순입력(간편식-책)"은 책 "재무제표 모르면 주식투자 절대로 하지 마라"에 소개된 계산식을 바탕으로 주황색 시트에 기초자료 입력하여 산출
B59: "[Type 2] 단순입력(성장반영 10년 시뮬레이션)"은 Type 1이 성장을 반영하지 못한다는(초과이익이 단순히 계속된다는 가정) 단점을 고려하여, 회사가 ROE를 유지하면 이익은 계속 증가한다는 점을 시뮬레이션을 통해 반영
B60: "[Type 3] 상세입력(성장반영 10년 시뮬레이션)"은 fnguide 화면 조회는 되나 붙여넣기가 안되는 경우(붙여넣기만 하면 컴퓨터가 다운되거나 먹통이 되는 등 개개인의 PC사정에 따라 다양한 경우가 있음)를 대비하여 주황색 란에 직접 fnguide 자료를 입력하여 산출
A62: 연도 오류 발생시 대처법
B63: Snapshot에 붙여넣을 때 연도 데이터는 날짜 형식으로 붙고, 일반숫자는 숫자 형식으로 붙게 되는데 새로 붙여 넣은 회사의 연도 위치가 다르면 주변서식에 맞추기를 선택했을 때 날짜가 일반 숫자 형식으로 인식되어 오류가 발생함
B64: 해결 방법은 기존에 인식된 서식을 지우는 것임
B65: FN_Snapshot의 A부터 I까지의 열을 선택한 다음 홈 메뉴의 지우기 - '모두 지우기' 나 '서식 지우기'를 선택하면 됨
B66: 이렇게 서식을 지운 다음 다시 '주변서식에 맞추기'로 붙여 넣으면 됩니다.
A76: 업데이트 내용
B77: (V30)
B78: Snapshot만 붙여 넣어도 되도록 변경(재무제표와 컨센서스를 붙여 넣을 필요가 없습니다)
B79: 달라진 fnguide 양식 반영
B80: RIM수기계산 시트 추가
B81: 업종비교 추가
B83: (V31)
B84: 연도 오류 발생시 대처법 추가
B86: (V32)
B87: 일부 신규상장 종목에 대한 오류 개선
B89: (V33)
B90: 컨센서스 이용시 컨센 3년 + 10년으로 총 13년의 초과이익을 가져오던 것을, 다른 방법과 동일하게 3년+7년으로 10년을 가져와 계산하도록 변경
A92: 참고영상
B93: 실적이 좋아져도 주가가 빠지는 이유 5분 정리 [헬프미 사프로 Ep.01]
B94: 영업이익은 마이너스, 그런데 현금흐름은 플러스? 이런 회사 괜찮을까? [헬프미 사프로 Ep.02]
B95: ROE가 큰 순환주기를 그리는 산업군, 평균값 어떻게 정하죠? [헬프미 사프로 Ep.03]
B96: 자산이라고 다 같은 자산이 아니다? [헬프미 사프로 Ep.04]
B97: 유상증자를 할 때 재무제표에서 살펴볼 것은? [헬프미 사프로 Ep.05]
B98: 복잡한 이벤트가 잦은 회사, 과연 투자해도 괜찮을까? [헬프미 사프로 Ep.06]

Sheet FN_Snapshot
A1: 본문 바로가기 메뉴 바로가기
A3: 상장기업분석
A5: 리포트 조회 통합 모바일앱 리타민 출시리포트 조회 통합 모바일앱 리타민 출시
A6: 열기
A7: 인쇄
A9: 기업정보
A10: Snapshot기업개요재무제표재무비율투자지표컨센서스
A11: 지분분석업종분석경쟁사비교거래소공시금감원공시
A12: ETF/ETN 정보
A13: ETF Snapshot 성과 및 위험분석 ETN Snapshot
A14: 리포트
A15: 리포트동향 요약리포트
... A26: 세방
A28: 5930
A30: | 홈페이지
A32: 홈페이지
A33: http://www.samsung.com
A35: 전화번호
A37: 전화번호
A38: 031-200-1114 | IR 담당자 02-2255-9000
A40: 주소
A42: 주소
A43: 경기도 수원시 영통구 삼성로 129 (매탄동)
A45: KSE 코스피 전기,전자코스피 전기,전자 |FICS 휴대폰 및 관련부품|12월 결산|K200
A47: PER(Price Earning Ratio)
A48: 전일자 보통주 수정주가 / 최근 결산 EPS(주당순이익)
... A51: PER
A52: 3
A54: 12M PER
A55: 전일자 보통주 수정주가 / 12개월 Forward EPS
A56: 12M PER
A57: 10.55
A59: 업종 PER
A60: 시장대표업종||SUM(구성종목 시가총액)/SUM(구성종목 당기순이익)
A61: * 전일자 보통주 시가총액 기준
A62: * 당기순이익은 최근결산 2021/12 (연간) 기준임.
A63: 업종 PER
A64: 6.31
A66: PBR(Price Book-value Ratio)
A67: 전일자 보통주 수정주가 / 최근 결산기 BPS(주당순자산)
...

Sheet 결과
B1: 공인회계사 사경인 | E1: 사경인 실전투자 아카데미
B3: 기초자료
B4: 회사명 | C4: =Data!B4 -> 세방 | D4: 보통주발행주수 | E4: =Data!B7 -> 19115603
B5: 현재주가 | C5: =Data!B5 -> 15770 | D5: 우선주발행주수 | E5: =Data!C7 -> 3689250
B6: 베타(β) | C6: =Data!B6 -> 0.54398 | D6: 자기주식 | E6: =Data!B8 -> 784733 | AD6: 적용 | AE6: 1순위 | AF6: =G24 -> 0.044408524 | AH6: 초과이익 가정
AD7: 미적용 | AE7: 컨센서스 | AF7: =E24 -> 컨센 없음 | AH7: 할인(할증)률
B8: Business Summary | AE8: 가중평균 | AF8: =F24 -> 0.080183333
B9: =Data!A11 -> 반도체 호조로 사상 최대 분기 실적 | AE9: 최근 | AF9: =H22 -> 0.044408524
B10: =Data!A12 -> 한국 및 CE, IM부문 해외 9개 지역총괄과 DS부문 해외 5개 지역총괄, Harman 등 234개의 종속기업으로 구성된 글로벌 전자기업임. 세트사업에는 TV, 냉장고 등을 생산하는 CE부문과 스마트폰, 네트워크시스템, 컴퓨터 등을 생산하는 IM부문이 있음. 부품사업(DS부문)에서는 D램, 낸드 플래쉬, 모바일AP 등의 제품을 생산하는 반도체 사업과 TFT-LCD 및 OLED 디스플레이 패널을 생산하는 DP사업으로 구성됨. | AE10: 별도값 | AF10: =H24 -> 0.13
B11: =Data!A13 -> 메모리시장이 호황인 가운데 폴더블폰과 OLED 판매가 늘어나 3분기 매출액은 70조를 넘어서며 사상 최대의 실적을 달성함. 첨단공정 확대와 환율 영향으로 영업이익률도 20%를 넘어섬. 4분기 메모리시장은 당초 예상 대비 부품 수급 이슈 장기화에 따른 수요 리스크 확대가 우려됨. 북미 서버업체들의 반도체 재고가 3분기 대비 30% 이상 축소되며 반도체 재고 소진 속도가 예상을 상회하여 반도체 가격 반등 시점이 앞당겨질 전망임.
B13: 요구수익률
B14: 별도 요구수익률 | C14: 적용 | D14: 0.1026
B15: 무위험이자율 | C15: 0.0152
B16: 시장위험프리미엄 | C16: 0.0657
B17: 최종 적용 할인율 | C17: =IF(C14="적용",D14,C15+C16*C6) -> 0.1026
B18: 참고링크 | C18: 채권수익률
B20: ROE 추정 | C20: 가중평균 | D20: =VLOOKUP(C20,AE6:AF10,2,FALSE) -> 0.080183333 | E20: =IF(I20="연도오류","연도 오류 - 모두 지우기 실행하세요(사용법 시트 참조)","") | I20: =IF(Data!B26<2000,"연도오류","")
B21: 년도 | C21: =Data!B25 -> 44166 | D21: =Data!C25 -> 44531 | E21: =Data!D25 -> 44896 | F21: =Data!E25 -> 45261 | G21: =Data!F25 -> 45627 | H21: ="최근 4분기("&TEXT(Data!F50,"yy/mm")&")" -> 최근 4분기(25/12) | I21: =IF(H22="분기자료부족",IF(F22>E22,IF(G22>F22,"상승추세",""),""),IF(F22>E22,IF(H22>F22,"상승추세",""),"")) | J21: =Data!K50 -> 12 | K21: =MONTH(G21) -> 12 | L21: =MOD(J21+12-K21,12)/6 -> 0 | M21: =L21+4 -> 4 | N21: =MOD(J21+12-K21,12) -> 0
B22: ROE | C22: =Data!B40 -> 0.0389 | D22: =Data!C40 -> 0.0601 | E22: =Data!D40 -> 0.1112 | F22: =Data!E40 -> 0.0678 | G22: =Data!F40 -> 0.0781 | H22: =Data!K78 -> 0.044408524 | I22: =IF(H22="분기자료부족",IF(F22<E22,IF(G22<F22,"하락추세",""),""),IF(F22<E22,IF(H22<F22,"하락추세",""),"")) -> 하락추세 | J22: =IF(H22="분기자료부족",IF(I21="상승추세",G22,IF(I22="하락추세",G22,F24)),"")
B23: 컨센서스 | C23: =DATE(Data!G26,12,31) -> 46022 | D23: =DATE(Data!H26,12,31) -> 46387 | E23: =DATE(Data!I26,12,31) -> 46752 | F23: 가중평균 | G23: 1순위 | H23: 별도값
B24: ROE | C24: =IF(Data!G40="","컨센 없음",Data!G40) -> 컨센 없음 | D24: =IF(Data!H40="","컨센 없음",Data!H40) -> 컨센 없음 | E24: =IF(Data!I40="","컨센 없음",Data!I40) -> 컨센 없음 | F24: =IF(H22="분기자료부족",(G22*3+F22*2+E22)/6,IF(N21=0,(G22*3+F22*2+E22)/6,(H22*3+G22*L21+F22)/M21)) -> 0.080183333 | G24: =IF(E24="컨센 없음",IF(D24="컨센 없음",IF(C24="컨센 없음",IF(H22="분기자료부족",J22,IF(I21="상승추세",H22,IF(I22="하락추세",H22,F24))),C24),D24),E24) -> 0.044408524 | H24: 0.13
B26: RIM 적정주가 | C26: 초과이익 가정 | D26: 0.2
B27: 현재주가 | C27: =C5 -> 15770 | D27: 적정가 대비 | E27: 주당 가치 | F27: 주가 | G27: PER
B28: 적정주가 | C28: =IF(F31="정배열",F29,F28) -> 49792.041 | D28: =C27/C28-1 -> -0.68328272 | E28: 초과이익 지속 | F28: =RIM계산!C11 -> 49792.041 | G28: =RIM계산!E11 -> 12.823704
B29: 매도가격 | C29: =IF(C26="초과이익 가정",IF(F31="정배열",F28,F30),C28*(1+D26)) -> 56843.424 | E29: 10%씩 감소 | F29: =RIM계산!C12 -> 54233.553 | G29: =RIM계산!E12 -> 13.967595
B30: 매수가격 | C30: =IF(C26="초과이익 가정",IF(F31="정배열",F30,F28),C28*(1-D26)) -> 49792.041 | E30: 20%씩 감소 | F30: =RIM계산!C13 -> 56843.424 | G30: =RIM계산!E13 -> 14.639755
F31: =IF(F28>F30,"정배열","역배열") -> 역배열 | G31: =IF(F31="정배열","ROE>요구수익","ROE<요구수익") -> ROE<요구수익
B33: 기타 참고사항 | C33: =C21 -> 44166 | D33: =D21 -> 44531 | E33: =E21 -> 44896 | F33: =F21 -> 45261 | G33: =G21 -> 45627 | H33: 올해 예상배당
B34: 주당배당금 | C34: =Data!B43 -> 190 | D34: =Data!C43 -> 200 | E34: =Data!D43 -> 300 | F34: =Data!E43 -> 300 | G34: =Data!F43 -> 300 | H34: =Data!G43 -> 0
B35: 배당수익률 | C35: =Data!B44 -> 0.0163 | D35: =Data!C44 -> 0.0167 | E35: =Data!D44 -> 0.0101 | F35: =Data!E44 -> 0.0245 | G35: =Data!F44 -> 0.0269 | H35: =H34/C27 -> 0
B36: =Data!A39 -> ROA(%) | C36: =Data!B39 -> 0.0286 | D36: =Data!C39 -> 0.0435 | E36: =Data!D39 -> 0.0836 | F36: =Data!E39 -> 0.0533 | G36: =Data!F39 -> 0.0605 | H36: =Data!G39 -> 0.1017
B37: =Data!A41 -> EPS(원) | C37: =Data!B41 -> 1415 | D37: =Data!C41 -> 2280 | E37: =Data!D41 -> 4583 | F37: =Data!E41 -> 3033 | G37: =Data!F41 -> 3716 | H37: =Data!G41 -> 0
B38: =Data!A42 -> BPS(원) | C38: =Data!B42 -> 37224 | D38: =Data!C42 -> 39392 | E38: =Data!D42 -> 44218 | F38: =Data!E42 -> 46680 | G38: =Data!F42 -> 50003 | H38: =Data!G42 -> 0
B39: 배당성향(DPS/EPS) | C39: =C34/C38 -> 0.0051042338 | D39: =D34/D38 -> 0.005077173 | E39: =E34/E38 -> 0.0067845674 | F39: =F34/F38 -> 0.0064267352 | G39: =G34/G38 -> 0.00599964 | H39: =H34/H38 -> #DIV/0!
B41: 업종 비교 | C41: =Data!B84 -> 세방 | D41: =Data!C84 -> 코스피 전기,전자 | E41: =Data!D84 -> KOSPI
B42: ROE | C42: =Data!B85 -> 0.0781 | D42: =Data!C85 -> 0.1134 | E42: =Data!D85 -> 0.0747
B43: PER | C43: =Data!B86 -> 3 | D43: =Data!C86 -> 6.31 | E43: =Data!D86 -> 22.35
B44: 배당수익률 | C44: =Data!B87 -> 0.0269 | D44: =Data!C87 -> 0.028 | E44: =Data!D87 -> 0.0228
B46: 순이익 예측

Sheet Data
A2: 기초자료
A4: 종목명 | B4: =OFFSET(INDIRECT(H4),2,0,1,1) -> 세방 | F4: 이용안내 | G4: =MATCH(F4,FN_Snapshot!A:A,0) -> 24 | H4: ="FN_Snapshot!A"&G4 -> FN_Snapshot!A24
A5: 종가/ 전일대비 | B5: =LEFT(I5,SEARCHB("/",I5)-1)*1 -> 15770 | G5: =MATCH(A5,FN_Snapshot!A:A,0) -> 114 | H5: ="FN_Snapshot!A"&G5 -> FN_Snapshot!A114 | I5: =OFFSET(INDIRECT(H5),0,1,1,1) -> 15,770/
A6: 베타(1년) | B6: =I6 -> 0.54398 | G6: =MATCH(A6,FN_Snapshot!C:C,0) -> 117 | H6: ="FN_Snapshot!C"&G6 -> FN_Snapshot!C117 | I6: =OFFSET(INDIRECT(H6),0,1,1,1) -> 0.54398
A7: 발행주식수(보통주/ 우선주) | B7: =LEFT(I7,SEARCHB("/",I7)-1)*1 -> 19115603 | C7: =RIGHT(I7,LEN(I7)-SEARCHB("/",I7))*1 -> 3689250 | G7: =MATCH(A7,FN_Snapshot!A:A,0) -> 128 | H7: ="FN_Snapshot!A"&G7 -> FN_Snapshot!A128 | I7: =OFFSET(INDIRECT(H7),0,1,1,1) -> 19,115,603/ 3,689,250
A8: 자기주식 (자사주+자사주신탁) | B8: =I8 -> 784733 | G8: =MATCH(A8,FN_Snapshot!A:A,0) -> 185 | H8: ="FN_Snapshot!A"&G8 -> FN_Snapshot!A185 | I8: =OFFSET(INDIRECT(H8),0,2,1,1) -> 784733
A10: Business Summary | G10: =MATCH(A10,FN_Snapshot!A:A,0) -> 232 | H10: ="FN_Snapshot!A"&G10 -> FN_Snapshot!A232
A11: =OFFSET(INDIRECT(H$10),4,0,1,1) -> 반도체 호조로 사상 최대 분기 실적
A12: =OFFSET(INDIRECT(H$10),6,0,1,1) -> 한국 및 CE, IM부문 해외 9개 지역총괄과 DS부문 해외 5개 지역총괄, Harman 등 234개의 종속기업으로 구성된 글로벌 전자기업임. 세트사업에는 TV, 냉장고 등을 생산하는 CE부문과 스마트폰, 네트워크시스템, 컴퓨터 등을 생산하는 IM부문이 있음. 부품사업(DS부문)에서는 D램, 낸드 플래쉬, 모바일AP 등의 제품을 생산하는 반도체 사업과 TFT-LCD 및 OLED 디스플레이 패널을 생산하는 DP사업으로 구성됨.
A13: =OFFSET(INDIRECT(H$10),7,0,1,1) -> 메모리시장이 호황인 가운데 폴더블폰과 OLED 판매가 늘어나 3분기 매출액은 70조를 넘어서며 사상 최대의 실적을 달성함. 첨단공정 확대와 환율 영향으로 영업이익률도 20%를 넘어섬. 4분기 메모리시장은 당초 예상 대비 부품 수급 이슈 장기화에 따른 수요 리스크 확대가 우려됨. 북미 서버업체들의 반도체 재고가 3분기 대비 30% 이상 축소되며 반도체 재고 소진 속도가 예상을 상회하여 반도체 가격 반등 시점이 앞당겨질 전망임.
A15: 가치평가 지표
A16: PER | B16: =I16 -> 3 | G16: =MATCH(A16,FN_Snapshot!A:A,0) -> 51 | H16: ="FN_Snapshot!A"&G16 -> FN_Snapshot!A51 | I16: =OFFSET(INDIRECT(H16),1,0,1,1) -> 3
A17: 12M PER | B17: =I17 -> 10.55 | G17: =MATCH(A17,FN_Snapshot!A:A,0) -> 54 | H17: ="FN_Snapshot!A"&G17 -> FN_Snapshot!A54 | I17: =OFFSET(INDIRECT(H17),3,0,1,1) -> 10.55
A18: 업종 PER | B18: =I18 -> 6.31 | G18: =MATCH(A18,FN_Snapshot!A:A,0) -> 59 | H18: ="FN_Snapshot!A"&G18 -> FN_Snapshot!A59 | I18: =OFFSET(INDIRECT(H18),5,0,1,1) -> 6.31
A19: EV/EBITDA | B19: =I19 -> 4.09 | G19: =MATCH(A19,FN_Snapshot!A:A,0) -> 286 | H19: ="FN_Snapshot!A"&G19 -> FN_Snapshot!A286 | I19: =OFFSET(INDIRECT(H19),0,1,1,1) -> 4.09
A20: PBR | B20: =I20 -> 0.22 | G20: =MATCH(A20,FN_Snapshot!A:A,0) -> 70 | H20: ="FN_Snapshot!A"&G20 -> FN_Snapshot!A70 | I20: =OFFSET(INDIRECT(H20),1,0,1,1) -> 0.22
A21: 배당수익률 | B21: =I21 -> 0.0269 | G21: =MATCH(A21,FN_Snapshot!A:A,0) -> 73 | H21: ="FN_Snapshot!A"&G21 -> FN_Snapshot!A73 | I21: =OFFSET(INDIRECT(H21),4,0,1,1) -> 0.0269
A23: Financial Highlight
F24: (배당금(보통주,현금) / 시가총액(보통)) * 100 | G24: =MATCH(F24,FN_Snapshot!A:A,0) -> 406 | H24: ="FN_Snapshot!A"&G24 -> FN_Snapshot!A406 | I24: =OFFSET(INDIRECT($H$24),3,0,1,1) -> Financial Highlight
B25: 44166 | C25: 44531 | D25: 44896 | E25: 45261 | F25: 45627 | G25: 45992 | H25: 46357 | I25: 46722
A26: IFRS(연결) | B26: 2020 | C26: 2021 | D26: 2022 | E26: 2023 | F26: 2024 | G26: 2025 | H26: 2026 | I26: 2027
A27: =OFFSET(INDIRECT($H$24),ROW()-18,COLUMN()-1,1,1) -> 매출액 | B27: 8422 | C27: 10577 | D27: 12904 | E27: 11420 | F27: 13734
A28: =OFFSET(INDIRECT($H$24),ROW()-18,COLUMN()-1,1,1) -> 영업이익 | B28: 164 | C28: 292 | D28: 451 | E28: 287 | F28: 245
A29: =OFFSET(INDIRECT($H$24),ROW()-18,COLUMN()-1,1,1) -> 영업이익(발표기준) | B29: 164 | C29: 292 | D29: 451 | E29: 287 | F29: 245 | G29: =IF(OFFSET(INDIRECT($H$24),ROW()-18,COLUMN()-1,1,1)=0,"",OFFSET(INDIRECT($H$24),ROW()-18,COLUMN()-1,1,1)) | H29: =IF(OFFSET(INDIRECT($H$24),ROW()-18,COLUMN()-1,1,1)=0,"",OFFSET(INDIRECT($H$24),ROW()-18,COLUMN()-1,1,1)) | I29: =IF(OFFSET(INDIRECT($H$24),ROW()-18,COLUMN()-1,1,1)=0,"",OFFSET(INDIRECT($H$24),ROW()-18,COLUMN()-1,1,1))
A30: =OFFSET(INDIRECT($H$24),ROW()-18,COLUMN()-1,1,1) -> 당기순이익 | B30: 326 | C30: 524 | D30: 1055 | E30: 700 | F30: 855
A31: =OFFSET(INDIRECT($H$24),ROW()-18,COLUMN()-1,1,1) -> 지배주주순이익 | B31: 325 | C31: 524 | D31: 1054 | E31: 698 | F31: 855
A32: =OFFSET(INDIRECT($H$24),ROW()-18,COLUMN()-1,1,1) -> 비지배주주순이익 | B32: 1 | C32: 0 | D32: 1 | E32: 2 | F32: 0 | G32: =IF(OFFSET(INDIRECT($H$24),ROW()-18,COLUMN()-1,1,1)=0,"",OFFSET(INDIRECT($H$24),ROW()-18,COLUMN()-1,1,1)) | H32: =IF(OFFSET(INDIRECT($H$24),ROW()-18,COLUMN()-1,1,1)=0,"",OFFSET(INDIRECT($H$24),ROW()-18,COLUMN()-1,1,1)) | I32: =IF(OFFSET(INDIRECT($H$24),ROW()-18,COLUMN()-1,1,1)=0,"",OFFSET(INDIRECT($H$24),ROW()-18,COLUMN()-1,1,1))
A33: =OFFSET(INDIRECT($H$24),ROW()-18,COLUMN()-1,1,1) -> 자산총계 | B33: 11646 | C33: 12449 | D33: 12810 | E33: 13452 | F33: 14803 | G33: =IF(OFFSET(INDIRECT($H$24),ROW()-18,COLUMN()-1,1,1)=0,"",OFFSET(INDIRECT($H$24),ROW()-18,COLUMN()-1,1,1)) -> 4561023 | H33: =IF(OFFSET(INDIRECT($H$24),ROW()-18,COLUMN()-1,1,1)=0,"",OFFSET(INDIRECT($H$24),ROW()-18,COLUMN()-1,1,1)) -> 4996128 | I33: =IF(OFFSET(INDIRECT($H$24),ROW()-18,COLUMN()-1,1,1)=0,"",OFFSET(INDIRECT($H$24),ROW()-18,COLUMN()-1,1,1))
A34: =OFFSET(INDIRECT($H$24),ROW()-18,COLUMN()-1,1,1) -> 부채총계 | B34: 3112 | C34: 3478 | D34: 2775 | E34: 2870 | F34: 3457 | G34: =IF(OFFSET(INDIRECT($H$24),ROW()-18,COLUMN()-1,1,1)=0,"",OFFSET(INDIRECT($H$24),ROW()-18,COLUMN()-1,1,1)) -> 1194703 | H34: =IF(OFFSET(INDIRECT($H$24),ROW()-18,COLUMN()-1,1,1)=0,"",OFFSET(INDIRECT($H$24),ROW()-18,COLUMN()-1,1,1)) -> 1240494 | I34: =IF(OFFSET(INDIRECT($H$24),ROW()-18,COLUMN()-1,1,1)=0,"",OFFSET(INDIRECT($H$24),ROW()-18,COLUMN()-1,1,1))
A35: =OFFSET(INDIRECT($H$24),ROW()-18,COLUMN()-1,1,1) -> 자본총계 | B35: 8534 | C35: 8972 | D35: 10035 | E35: 10582 | F35: 11346 | G35: =IF(OFFSET(INDIRECT($H$24),ROW()-18,COLUMN()-1,1,1)=0,"",OFFSET(INDIRECT($H$24),ROW()-18,COLUMN()-1,1,1)) -> 3366321 | H35: =IF(OFFSET(INDIRECT($H$24),ROW()-18,COLUMN()-1,1,1)=0,"",OFFSET(INDIRECT($H$24),ROW()-18,COLUMN()-1,1,1)) -> 3755639 | I35: =IF(OFFSET(INDIRECT($H$24),ROW()-18,COLUMN()-1,1,1)=0,"",OFFSET(INDIRECT($H$24),ROW()-18,COLUMN()-1,1,1))
A36: =OFFSET(INDIRECT($H$24),ROW()-18,COLUMN()-1,1,1) -> 지배주주지분 | B36: 8505 | C36: 8943 | D36: 10007 | E36: 10564 | F36: 11329
A37: =OFFSET(INDIRECT($H$24),ROW()-18,COLUMN()-1,1,1) -> 비지배주주지분 | B37: 30 | C37: 29 | D37: 28 | E37: 19 | F37: 17 | G37: =IF(OFFSET(INDIRECT($H$24),ROW()-18,COLUMN()-1,1,1)=0,"",OFFSET(INDIRECT($H$24),ROW()-18,COLUMN()-1,1,1)) -> 99222 | H37: =IF(OFFSET(INDIRECT($H$24),ROW()-18,COLUMN()-1,1,1)=0,"",OFFSET(INDIRECT($H$24),ROW()-18,COLUMN()-1,1,1)) -> 111326 | I37: =IF(OFFSET(INDIRECT($H$24),ROW()-18,COLUMN()-1,1,1)=0,"",OFFSET(INDIRECT($H$24),ROW()-18,COLUMN()-1,1,1))
A38: =OFFSET(INDIRECT($H$24),ROW()-18,COLUMN()-1,1,1) -> 자본금 | B38: 115 | C38: 115 | D38: 115 | E38: 115 | F38: 115 | G38: =IF(OFFSET(INDIRECT($H$24),ROW()-18,COLUMN()-1,1,1)=0,"",OFFSET(INDIRECT($H$24),ROW()-18,COLUMN()-1,1,1)) -> 8979 | H38: =IF(OFFSET(INDIRECT($H$24),ROW()-18,COLUMN()-1,1,1)=0,"",OFFSET(INDIRECT($H$24),ROW()-18,COLUMN()-1,1,1)) -> 8979 | I38: =IF(OFFSET(INDIRECT($H$24),ROW()-18,COLUMN()-1,1,1)=0,"",OFFSET(INDIRECT($H$24),ROW()-18,COLUMN()-1,1,1))
A39: =OFFSET(INDIRECT($H$24),ROW()-2,COLUMN()-1,1,1) -> ROA(%) | B39: =OFFSET(INDIRECT($H$24),ROW()-2,COLUMN()-1,1,1)/100 -> 0.0286 | C39: =OFFSET(INDIRECT($H$24),ROW()-2,COLUMN()-1,1,1)/100 -> 0.0435 | D39: =OFFSET(INDIRECT($H$24),ROW()-2,COLUMN()-1,1,1)/100 -> 0.0836 | E39: =OFFSET(INDIRECT($H$24),ROW()-2,COLUMN()-1,1,1)/100 -> 0.0533 | F39: =OFFSET(INDIRECT($H$24),ROW()-2,COLUMN()-1,1,1)/100 -> 0.0605 | G39: =IF(OFFSET(INDIRECT($H$24),ROW()-2,COLUMN()-1,1,1)=0,"",OFFSET(INDIRECT($H$24),ROW()-2,COLUMN()-1,1,1)/100) -> 0.1017 | H39: =IF(OFFSET(INDIRECT($H$24),ROW()-2,COLUMN()-1,1,1)=0,"",OFFSET(INDIRECT($H$24),ROW()-2,COLUMN()-1,1,1)/100) -> 0.11 | I39: =IF(OFFSET(INDIRECT($H$24),ROW()-2,COLUMN()-1,1,1)=0,"",OFFSET(INDIRECT($H$24),ROW()-2,COLUMN()-1,1,1)/100) -> 0.1171
A40: =OFFSET(INDIRECT($H$24),ROW()+1,COLUMN()-1,1,1) -> ROE(%) | B40: 0.0389 | C40: 0.0601 | D40: 0.1112 | E40: 0.0678 | F40: 0.0781
A41: =OFFSET(INDIRECT($H$24),ROW()+4,COLUMN()-1,1,1) -> EPS(원) | B41: 1415 | C41: 2280 | D41: 4583 | E41: 3033 | F41: 3716
A42: =OFFSET(INDIRECT($H$24),ROW()+7,COLUMN()-1,1,1) -> BPS(원) | B42: 37224 | C42: 39392 | D42: 44218 | E42: 46680 | F42: 50003
A43: =OFFSET(INDIRECT($H$24),ROW()+10,COLUMN()-1,1,1) -> DPS(원) | B43: 190 | C43: 200 | D43: 300 | E43: 300 | F43: 300
A44: =OFFSET(INDIRECT($H$24),ROW()+22,COLUMN()-1,1,1) -> 배당수익률(%) | B44: 0.0163 | C44: 0.0167 | D44: 0.0101 | E44: 0.0245 | F44: 0.0269
A50: IFRS(연결) | B50: =OFFSET(INDIRECT($H$24),72,1,1,1) -> 45717 | C50: =OFFSET(INDIRECT($H$24),72,2,1,1) -> 45809 | D50: =OFFSET(INDIRECT($H$24),72,3,1,1) -> 45901 | E50: =OFFSET(INDIRECT($H$24),72,4,1,1) -> 45992 | F50: =OFFSET(INDIRECT($H$24),72,5,1,1) -> 45992 | K50: =MONTH(F50) -> 12
...

Sheet RIM계산
A2: 최근 결산연도 | B2: =Data!F26 -> 2024 | D2: ROE | E2: =Data!B40 -> 0.0389 | F2: =Data!C40 -> 0.0601 | G2: =Data!D40 -> 0.1112 | H2: =Data!E40 -> 0.0678 | I2: =Data!F40 -> 0.0781 | J2: =Data!G40 -> 0 | K2: =Data!H40 -> 0 | L2: =Data!I40 -> 0 | M2: =Data!K78 -> 0.044408524
A3: 요구수익률 | B3: =결과!D14 -> 0.1026 | D3: 지배주주지분 | E3: =Data!B36 -> 8505 | F3: =Data!C36 -> 8943 | G3: =Data!D36 -> 10007 | H3: =Data!E36 -> 10564 | I3: =Data!F36 -> 11329 | J3: =Data!G36 -> 0 | K3: =Data!H36 -> 0 | L3: =Data!I36 -> 0 | M3: =IF(ISERR(Data!K61),IF(Data!K69=0,Data!F36,Data!F75),Data!F60) -> 11956
A4: 발행주식수(보통+우선) | B4: =Data!B7+Data!C7 -> 22804853 | D4: 년도 | E4: =DATE(Data!B26,12,31) -> 44196 | F4: =DATE(Data!C26,12,31) -> 44561 | G4: =DATE(Data!D26,12,31) -> 44926 | H4: =DATE(Data!E26,12,31) -> 45291 | I4: =DATE(Data!F26,12,31) -> 45657 | J4: =DATE(Data!G26,12,31) -> 46022 | K4: =DATE(Data!H26,12,31) -> 46387 | L4: =DATE(Data!I26,12,31) -> 46752 | M4: =EOMONTH(Data!F50,0) -> 46022
A5: 자기주식 | B5: =Data!B8 -> 784733 | D5: 지배주주순이익 | E5: =Data!B31 -> 325 | F5: =Data!C31 -> 524 | G5: =Data!D31 -> 1054 | H5: =Data!E31 -> 698 | I5: =Data!F31 -> 855 | J5: =Data!G31 -> 0 | K5: =Data!H31 -> 0 | L5: =Data!I31 -> 0 | M5: =IF(ISERR(Data!K61),IF(Data!K69=0,Data!F31,Data!K72),Data!K55) -> 522
A7: ROE 추정 | B7: =결과!D20 -> 0.080183333 | E7: 분석기준시점 | F7: 45657 | G7: 현재 | H7: =TODAY() -> 46101 | I7: 분석종료시점 | J7: 2034
E8: 기준시점 주주지분 | F8: =IF(ISNA(HLOOKUP(B7,$E$2:$M$3,2,FALSE)),M3,HLOOKUP(B7,$E$2:$M$3,2,FALSE)) -> 11956 | G8: 기준시점-현재 | H8: =F7-H7 -> -444
A10: 초과이익 가정 | B10: 적정주주가치 | C10: 적정주가 | D10: 판단 | E10: PER
A11: 지속 | B11: =C25 -> 10964.267 | C11: =C26 -> 49792.041 | D11: 매도가격 | E11: =B11/$I$5 -> 12.823704
A12: 10%씩 감소 | B12: =C38 -> 11942.294 | C12: =C39 -> 54233.553 | D12: 적정가격 | E12: =B12/$I$5 -> 13.967595
A13: 20%씩 감소 | B13: =C51 -> 12516.99 | C13: =C52 -> 56843.424 | D13: 매수가격 | E13: =B13/$I$5 -> 14.639755
A15: 초과이익 지속계수 | B15: 1
A16: 시점 | B16: =$F$7 -> 45657 | C16: =B16+365 -> 46022 | D16: =C16+365 -> 46387 | E16: =D16+365 -> 46752 | F16: =E16+365 -> 47117 | G16: =F16+365 -> 47482 | H16: =G16+365 -> 47847 | I16: =H16+365 -> 48212 | J16: =I16+365 -> 48577 | ... L16: =K16+365 -> 49307
A17: 요구수익률 | B17: =$B$3 -> 0.1026 | C17: =B17 -> 0.1026 | D17: =C17 -> 0.1026 | E17: =D17 -> 0.1026 | F17: =E17 -> 0.1026 | G17: =F17 -> 0.1026 | H17: =G17 -> 0.1026 | I17: =H17 -> 0.1026 | J17: =I17 -> 0.1026 | ... L17: =K17 -> 0.1026
A18: 초과이익률 | B18: =$B$7-B17 -> -0.022416667 | C18: =IF(YEAR(C16)>$J$7,0,B18*$B$15) -> -0.022416667 | D18: =IF(YEAR(D16)>$J$7,0,C18*$B$15) -> -0.022416667 | E18: =IF(YEAR(E16)>$J$7,0,D18*$B$15) -> -0.022416667 | F18: =IF(YEAR(F16)>$J$7,0,E18*$B$15) -> -0.022416667 | G18: =IF(YEAR(G16)>$J$7,0,F18*$B$15) -> -0.022416667 | H18: =IF(YEAR(H16)>$J$7,0,G18*$B$15) -> -0.022416667 | I18: =IF(YEAR(I16)>$J$7,0,H18*$B$15) -> -0.022416667 | J18: =IF(YEAR(J16)>$J$7,0,I18*$B$15) -> -0.022416667 | ... L18: =IF(YEAR(L16)>$J$7,0,K18*$B$15) -> -0.022416667
A19: ROE | B19: =B17+B18 -> 0.080183333 | C19: =C17+C18 -> 0.080183333 | D19: =D17+D18 -> 0.080183333 | E19: =E17+E18 -> 0.080183333 | F19: =F17+F18 -> 0.080183333 | G19: =G17+G18 -> 0.080183333 | H19: =H17+H18 -> 0.080183333 | I19: =I17+I18 -> 0.080183333 | ... L19: =L17+L18 -> 0.080183333
A20: 지배주주순이익 | C20: =B21*C19 -> 958.67193 | D20: =C21*D19 -> 1035.5414 | E20: =D21*E19 -> 1118.5746 | F20: =E21*F19 -> 1208.2657 | G20: =F21*G19 -> 1305.1484 | H20: =G21*H19 -> 1409.7996 | I20: =H21*I19 -> 1522.842 | J20: =I21*J19 -> 1644.9485 | ... L20: =K21*L19 -> 1919.3194
A21: 지배주주지분 | B21: =$F$8 -> 11956 | C21: =B21+C20 -> 12914.672 | D21: =C21+D20 -> 13950.213 | E21: =D21+E20 -> 15068.788 | F21: =E21+F20 -> 16277.054 | G21: =F21+G20 -> 17582.202 | H21: =G21+H20 -> 18992.002 | I21: =H21+I20 -> 20514.844 | J21: =I21+J20 -> 22159.792 | ... L21: =K21+L20 -> 25855.958
A22: 초과이익 | C22: =C20-B21*C17 -> -268.01367 | D22: =D20-C21*D17 -> -289.5039 | E22: =E20-D21*E17 -> -312.71728 | F22: =F20-E21*F17 -> -337.792 | G22: =G20-F21*G17 -> -364.87729 | H22: =H20-G21*H17 -> -394.13436 | I22: =I20-H21*I17 -> -425.73737 | J22: =J20-I21*J17 -> -459.87441 | ... L22: =L20-K21*L17 -> -536.57964
A23: PV of RI | B23: =NPV($B$3,C22:L22) -> -2219.996
B24: 분석시점 기준 | C24: 현재 기준
A25: RIM 주주가치 | B25: =B21+B23 -> 9736.004 | C25: =B25/(1+$B$3)^($H$8/365) -> 10964.267
A26: RIM 적정주가 | B26: =B25*100000000/($B$4-$B$5) -> 44214.128 | C26: =B26/(1+$B$3)^($H$8/365) -> 49792.041
A28: 초과이익 지속계수 | B28: 0.9
A29: 시점 | B29: =$F$7 -> 45657 | C29: =B29+365 -> 46022 | D29: =C29+365 -> 46387 | E29: =D29+365 -> 46752 | F29: =E29+365 -> 47117 | G29: =F29+365 -> 47482 | H29: =G29+365 -> 47847 | I29: =H29+365 -> 48212 | J29: =I29+365 -> 48577 | ... L29: =K29+365 -> 49307
A30: 요구수익률 | B30: =$B$3 -> 0.1026 | C30: =B30 -> 0.1026 | D30: =C30 -> 0.1026 | E30: =D30 -> 0.1026 | F30: =E30 -> 0.1026 | G30: =F30 -> 0.1026 | H30: =G30 -> 0.1026 | I30: =H30 -> 0.1026 | J30: =I30 -> 0.1026 | ... L30: =K30 -> 0.1026
A31: 초과이익률 | B31: =$B$7-B30 -> -0.022416667 | C31: =IF(YEAR(C16)>$J$7,0,B31*$B$28) -> -0.020175 | D31: =IF(YEAR(D16)>$J$7,0,C31*$B$28) -> -0.0181575 | E31: =IF(YEAR(E16)>$J$7,0,D31*$B$28) -> -0.01634175 | F31: =IF(YEAR(F16)>$J$7,0,E31*$B$28) -> -0.014707575 | G31: =IF(YEAR(G16)>$J$7,0,F31*$B$28) -> -0.013236818 | H31: =IF(YEAR(H16)>$J$7,0,G31*$B$28) -> -0.011913136 | I31: =IF(YEAR(I16)>$J$7,0,H31*$B$28) -> -0.010721822 | J31: =IF(YEAR(J16)>$J$7,0,I31*$B$28) -> -0.00964964 | ... L31: =IF(YEAR(L16)>$J$7,0,K31*$B$28) -> -0.0078162084
A32: ROE | B32: =B30+B31 -> 0.080183333 | C32: =C30+C31 -> 0.082425 | D32: =D30+D31 -> 0.0844425 | E32: =E30+E31 -> 0.08625825 | F32: =F30+F31 -> 0.087892425 | G32: =G30+G31 -> 0.089363182 | H32: =H30+H31 -> 0.090686864 | I32: =I30+I31 -> 0.091878178 | ... L32: =L30+L31 -> 0.094783792
A33: 지배주주순이익 | C33: =B34*C32 -> 985.4733 | D33: =C34*D32 -> 1092.8104 | E33: =D34*E32 -> 1210.5727 | F33: =E34*F32 -> 1339.9074 | G33: =F34*G32 -> 1482.0673 | H33: =G34*H32 -> 1638.4243 | I33: =H34*I32 -> 1810.483 | J33: =I34*J32 -> 1999.8956 | ... L33: =K34*L32 -> 2438.2289
A34: 지배주주지분 | B34: =$F$8 -> 11956 | C34: =B34+C33 -> 12941.473 | D34: =C34+D33 -> 14034.284 | E34: =D34+E33 -> 15244.856 | F34: =E34+F33 -> 16584.764 | G34: =F34+G33 -> 18066.831 | H34: =G34+H33 -> 19705.255 | I34: =H34+I33 -> 21515.738 | J34: =I34+J33 -> 23515.634 | ... L34: =K34+L33 -> 28162.341
A35: 초과이익 | C35: =C33-B34*C30 -> -241.2123 | D35: =D33-C34*D30 -> -234.9848 | E35: =E33-D34*E30 -> -229.34475 | F35: =F33-E34*F30 -> -224.21487 | G35: =G33-F34*G30 -> -219.52949 | H35: =H33-G34*H30 -> -215.23261 | I35: =I33-H34*I30 -> -211.27624 | J35: =J33-I34*J30 -> -207.61913 | ... L35: =L33-K34*L30 -> -201.06502
A36: PV of RI | B36: =NPV($B$3,C35:L35) -> -1351.5323
B37: 분석시점 기준 | C37: 현재 기준
A38: RIM 주주가치 | B38: =B34+B36 -> 10604.468 | C38: =B38/(1+$B$3)^($H$8/365) -> 11942.294
A39: RIM 적정주가 | B39: =B38*100000000/($B$4-$B$5) -> 48158.083 | C39: =B39/(1+$B$3)^($H$8/365) -> 54233.553
A41: 초과이익 지속계수 | B41: 0.8
A42: 시점 | B42: =$F$7 -> 45657 | C42: =B42+365 -> 46022 | D42: =C42+365 -> 46387 | E42: =D42+365 -> 46752 | F42: =E42+365 -> 47117 | G42: =F42+365 -> 47482 | H42: =G42+365 -> 47847 | I42: =H42+365 -> 48212 | J42: =I42+365 -> 48577 | ... L42: =K42+365 -> 49307
A43: 요구수익률 | B43: =$B$3 -> 0.1026 | C43: =B43 -> 0.1026 | D43: =C43 -> 0.1026 | E43: =D43 -> 0.1026 | F43: =E43 -> 0.1026 | G43: =F43 -> 0.1026 | H43: =G43 -> 0.1026 | I43: =H43 -> 0.1026 | J43: =I43 -> 0.1026 | ... L43: =K43 -> 0.1026
A44: 초과이익률 | B44: =$B$7-B43 -> -0.022416667 | C44: =IF(YEAR(C16)>$J$7,0,B44*$B$41) -> -0.017933333 | D44: =IF(YEAR(D16)>$J$7,0,C44*$B$41) -> -0.014346667 | E44: =IF(YEAR(E16)>$J$7,0,D44*$B$41) -> -0.011477333 | F44: =IF(YEAR(F16)>$J$7,0,E44*$B$41) -> -0.0091818667 | G44: =IF(YEAR(G16)>$J$7,0,F44*$B$41) -> -0.0073454933 | H44: =IF(YEAR(H16)>$J$7,0,G44*$B$41) -> -0.0058763947 | I44: =IF(YEAR(I16)>$J$7,0,H44*$B$41) -> -0.0047011157 | J44: =IF(YEAR(J16)>$J$7,0,I44*$B$41) -> -0.0037608926 | ... L44: =IF(YEAR(L16)>$J$7,0,K44*$B$41) -> -0.0024069713
A45: ROE | B45: =B43+B44 -> 0.080183333 | C45: =C43+C44 -> 0.084666667 | D45: =D43+D44 -> 0.088253333 | E45: =E43+E44 -> 0.091122667 | F45: =F43+F44 -> 0.093418133 | G45: =G43+G44 -> 0.095254507 | H45: =H43+H44 -> 0.096723605 | I45: =I43+I44 -> 0.097898884 | ... L45: =L43+L44 -> 0.10019303
A46: 지배주주순이익 | C46: =B47*C45 -> 1012.2747 | D46: =C47*D45 -> 1144.4935 | E46: =D47*E45 -> 1285.9931 | F46: =E47*F45 -> 1438.5235 | G46: =F47*G45 -> 1603.8273 | H46: =G47*H45 -> 1783.6908 | I46: =H47*I45 -> 1979.9856 | J46: =I47*J45 -> 2194.7015 | ... L46: =K47*L45 -> 2688.1255
...

Sheet RIM수기계산
A1: 주황색 셀만 입력하거나 선택합니다.
A3: [Type 1] 단순입력(간편식-책)
A5: 자기자본 | B5: 1513
A6: 예상 ROE | B6: 0.1522
A7: 요구수익률(할인률) | B7: 0.0805
A8: 기업가치 | B8: =B5+(B5*(B6-B7))/B7 -> 2860.6037
A10: 주식수 | B10: 15179843
A11: 적정주가 | B11: =B8*100000000/B10 -> 18844.752
A13: 초과이익 가정 | B13: 적정주주가치 | C13: 적정주가 | D13: 판단 | F13: 초과이익 | G13: =B5*(B6-B7) -> 108.4821
A14: 지속 | B14: =B8 -> 2860.6037 | C14: =B11 -> 18844.752 | D14: 매도가격 | F14: 지속계수
A15: 10%씩 감소 | B15: =B5+G13*F15/(1+B7-F15) -> 2053.908 | C15: =B15*100000000/B10 -> 13530.496 | D15: 적정가격 | F15: 0.9
A16: 20%씩 감소 | B16: =B5+G13*F16/(1+B7-F16) -> 1822.3964 | C16: =B16*100000000/B10 -> 12005.37 | D16: 매수가격 | F16: 0.8
A18: [Type 2] 단순입력(성장반영 10년 시뮬레이션)
A20: 초과이익 가정 | B20: 적정주주가치 | C20: 적정주가 | D20: 판단
A21: 지속 | B21: =B34 -> 2876.5367 | C21: =B35 -> 18949.713 | D21: 매도가격
A22: 10%씩 감소 | B22: =B46 -> 2214.6094 | C22: =B47 -> 14589.146 | D22: 적정가격
A23: 20%씩 감소 | B23: =B58 -> 1910.2924 | C23: =B59 -> 12584.401 | D23: 매수가격
A25: 초과이익 지속계수 | B25: 1
A26: 시점 | B26: Y-0 | C26: Y-1 | D26: Y-2 | E26: Y-3 | F26: Y-4 | G26: Y-5 | H26: Y-6 | I26: Y-7 | J26: Y-8 | K26: Y-9 | L26: Y-10
A27: 요구수익률 | B27: =$B$7 -> 0.0805 | C27: =B27 -> 0.0805 | D27: =C27 -> 0.0805 | E27: =D27 -> 0.0805 | F27: =E27 -> 0.0805 | G27: =F27 -> 0.0805 | H27: =G27 -> 0.0805 | I27: =H27 -> 0.0805 | J27: =I27 -> 0.0805 | ... L27: =K27 -> 0.0805
A28: 초과이익률 | B28: =$B$6-B27 -> 0.0717 | C28: =B28*$B$25 -> 0.0717 | D28: =C28*$B$25 -> 0.0717 | E28: =D28*$B$25 -> 0.0717 | F28: =E28*$B$25 -> 0.0717 | G28: =F28*$B$25 -> 0.0717 | H28: =G28*$B$25 -> 0.0717 | I28: =H28*$B$25 -> 0.0717 | J28: =I28*$B$25 -> 0.0717 | ... L28: =K28*$B$25 -> 0.0717
A29: ROE | B29: =B27+B28 -> 0.1522 | C29: =C27+C28 -> 0.1522 | D29: =D27+D28 -> 0.1522 | E29: =E27+E28 -> 0.1522 | F29: =F27+F28 -> 0.1522 | G29: =G27+G28 -> 0.1522 | H29: =H27+H28 -> 0.1522 | I29: =I27+I28 -> 0.1522 | ... L29: =L27+L28 -> 0.1522
A30: 지배주주순이익 | C30: =B31*C29 -> 230.2786 | D30: =C31*D29 -> 265.327 | E30: =D31*E29 -> 305.70977 | F30: =E31*F29 -> 352.2388 | G30: =F31*G29 -> 405.84955 | H30: =G31*H29 -> 467.61985 | I30: =H31*I29 -> 538.79159 | J30: =I31*J29 -> 620.79567 | ... L30: =K31*L29 -> 824.1465
A31: 지배주주지분 | B31: =$B$5 -> 1513 | C31: =B31+C30 -> 1743.2786 | D31: =C31+D30 -> 2008.6056 | E31: =D31+E30 -> 2314.3154 | F31: =E31+F30 -> 2666.5542 | G31: =F31+G30 -> 3072.4037 | H31: =G31+H30 -> 3540.0236 | I31: =H31+I30 -> 4078.8152 | J31: =I31+J30 -> 4699.6108 | ... L31: =K31+L30 -> 6239.0381
A32: 초과이익 | C32: =C30-B31*C27 -> 108.4821 | D32: =D30-C31*D27 -> 124.99308 | E32: =E30-D31*E27 -> 144.01702 | F32: =F30-E31*F27 -> 165.93641 | G32: =G30-F31*G27 -> 191.19193 | H32: =H30-G31*H27 -> 220.29135 | I32: =I30-H31*I27 -> 253.81969 | J32: =J30-I31*J27 -> 292.45105 | ... L32: =L30-K31*L27 -> 388.24773
A33: PV of RI | B33: =NPV($B$7,C32:L32) -> 1363.5367
A34: RIM 주주가치 | B34: =B31+B33 -> 2876.5367
A35: RIM 적정주가 | B35: =B34*100000000/$B$10 -> 18949.713
A37: 초과이익 지속계수 | B37: 0.9
A38: 시점 | B38: Y-0 | C38: Y-1 | D38: Y-2 | E38: Y-3 | F38: Y-4 | G38: Y-5 | H38: Y-6 | I38: Y-7 | J38: Y-8 | K38: Y-9 | L38: Y-10
A39: 요구수익률 | B39: =$B$7 -> 0.0805 | C39: =B39 -> 0.0805 | D39: =C39 -> 0.0805 | E39: =D39 -> 0.0805 | F39: =E39 -> 0.0805 | G39: =F39 -> 0.0805 | H39: =G39 -> 0.0805 | I39: =H39 -> 0.0805 | J39: =I39 -> 0.0805 | ... L39: =K39 -> 0.0805
A40: 초과이익률 | B40: =$B$6-B39 -> 0.0717 | C40: =B40*$B$37 -> 0.06453 | D40: =C40*$B$37 -> 0.058077 | E40: =D40*$B$37 -> 0.0522693 | F40: =E40*$B$37 -> 0.04704237 | G40: =F40*$B$37 -> 0.042338133 | H40: =G40*$B$37 -> 0.03810432 | I40: =H40*$B$37 -> 0.034293888 | J40: =I40*$B$37 -> 0.030864499 | ... L40: =K40*$B$37 -> 0.025000244
A41: ROE | B41: =B39+B40 -> 0.1522 | C41: =C39+C40 -> 0.14503 | D41: =D39+D40 -> 0.138577 | E41: =E39+E40 -> 0.1327693 | F41: =F39+F40 -> 0.12754237 | G41: =G39+G40 -> 0.12283813 | H41: =H39+H40 -> 0.11860432 | I41: =I39+I40 -> 0.11479389 | ... L41: =L39+L40 -> 0.10550024
A42: 지배주주순이익 | C42: =B43*C41 -> 219.43039 | D42: =C43*D41 -> 240.07501 | E42: =D43*E41 -> 261.88816 | F42: =E43*F41 -> 284.97985 | G42: =F43*G41 -> 309.47513 | H42: =G43*H41 -> 335.51366 | I42: =H43*I41 -> 363.24944 | J42: =I43*J41 -> 392.8507 | ... L42: =K43*L41 -> 458.39459
A43: 지배주주지분 | B43: =$B$5 -> 1513 | C43: =B43+C42 -> 1732.4304 | D43: =C43+D42 -> 1972.5054 | E43: =D43+E42 -> 2234.3936 | F43: =E43+F42 -> 2519.3734 | G43: =F43+G42 -> 2828.8485 | H43: =G43+H42 -> 3164.3622 | I43: =H43+I42 -> 3527.6116 | J43: =I43+J42 -> 3920.4623 | ... L43: =K43+L42 -> 4803.3569
A44: 초과이익 | C44: =C42-B43*C39 -> 97.63389 | D44: =D42-C43*D39 -> 100.61436 | E44: =E42-D43*E39 -> 103.10148 | F44: =F42-E43*F39 -> 105.11117 | G44: =G42-F43*G39 -> 106.66557 | H44: =H42-G43*H39 -> 107.79135 | I44: =I42-H43*I39 -> 108.51828 | J44: =J42-I43*J39 -> 108.87797 | ... L44: =L42-K43*L39 -> 108.62512
A45: PV of RI | B45: =NPV($B$7,C44:L44) -> 701.60944
A46: RIM 주주가치 | B46: =B43+B45 -> 2214.6094
A47: RIM 적정주가 | B47: =B46*100000000/$B$10 -> 14589.146
A49: 초과이익 지속계수 | B49: 0.8
...
